Workbook

Sheet Corpus
A1: id | B1: titre | C1: album | D1: artiste | E1: nb_mots | F1: nb_lignes | G1: paroles_propres | H1: balises_retirees | I1: url_source | J1: date_collecte
A2: 2 | B2: Action Men | C2: .RAW | D2: Laylow | E2: 334 | F2: 47 | G2: Ma money, ma money, ma J'les baiserai dans l'anonymat Au jeu d'l'enfer , y'a beaucoup d'candidats Depuis tit-pe, des billets dans la tête donc on grandit pas Han, j'suis dans mes pensées infinies, mets le diamant sur le vinyle Han, tu veux la coke, j'serai ton pilote de ligne J'arrive vite comme un homme libre Les gens qui mentent, ça me nuit, les sentiments s'amenuisent J'écris des lignes avec les larmes de mes ennemis Fais money dans la ville, j'mets salaire dans la nuit Cherche trésor dans la mine, DigitalMundo ma vie Au-dessus des lois, au-dessus des lois Fais pleurer ta chatte au-dessus de moi J'ai que des sales idées décidement, oh wow T'es pas ma dulcinée, pas d'cinéma J'ai touché ton cœur, j'ai pas mis les mains Dans les étoiles comme Faucon Millenium, oh, yeah Gauche, droite, vision rouge J'roule pétard d'vant le bleu qui tourne Tout l'club transpire comme à Mexico Oooh Police cherche le bout, solide sont les troupes Folie dans mon groove, shawty veut son coup Money mon amour, j'mets son molly et tout à coup, yeah J'rentre en bolide dans ta couette Il est six du mat', va dire à ta pote elle fait trop d'manières Dis-lui que l'appartement est haussmannien Dis-lui qu'elle a pas besoin de porte-monnaie yeah, on sait pas se contrôler Depuis qu'elle est jamais dans le compromis Donc on récupère cette monnaie Elle est plus sweet que des Jette-moi la , t'es comme ma génération Des accélérations Micro branché, j'suis dans ma chambre Arrête ces , augmente les basses J'danse comme Jimmy Quid dans rock'n'rolla Tout est noir dans l'scénario qu'on relate Jusqu'où t'irais pour soutirer ta poignée d'dollars ? Gauche, droite, vision rouge J'roule pétard d'vant le bleu qui tourne Tout l'club transpire comme à Mexico Oooh Police cherche le bout, solide sont les troupes Folie dans mon groove, shawty veut son coup Money mon amour, j'mets son molly et tout à coup, yeah J'rentre en bolide dans ta couette | H2: Wit | gentils moi ? | Wit & Laylow | Laylow | ? | ? | ? | ? | Wit & Laylow | I2: https://www.paroles.net/laylow/paroles-action-men | J2: 2026-10-21
A3: 6 | B3: Avenue | C3: .RAW | D3: Laylow | E3: 396 | F3: 40 | G3: Elle voit pas ça d'un bon œil quand j'suis rock'n'rolla Nan, nan, shawty veut mon nom, nom D'habitude "no love", d'habitude, j'suis dans ma paranoïa Bloqué dans ma noyade, ouh, j'entends le chant des Naïades Owowo, la basse qui fait "dowowo" Là, ça glisse, glisse, glisse mais la fin sera triste, triste, triste Jeune nigga dans ce biz' fait l'biff dans une ville plein d'vices Téléphone : dring dring dring Elle attend ma venue, ma venue, j'suis sur l'avenue, l'avenue J'ai aimé nos vacances à Venise mais je sais qu'le printemps va finir Elle attend ma venue, ma venue, ma venue, ma venue J'suis sur l'avenue, l'avenue, hey, hey Elle attend ma venue, ma venue, j'suis sur l'avenue, l'avenue J'ai aimé nos vacances à Venise mais je sais qu'le printemps va finir Elle attend ma venue, ma venue, j'suis sur l'avenue, l'avenue eh Elle attend ma venue, ma venue, j'suis sur l'avenue, l'avenue God damn, j'ai des soucis dans la tête, toi, t'es là avec ton soutif en latex J'mets la mélo dans la caisse, j'finis l'couplet dans la cabine, il est six (o'clock) Oh Maria, j's'rai en retard à mon mariage C'est dommage comme pour Aaliyah, là, je ride, je suis pas loin de ton barrio "Allô, t'es où ?", "J'suis là, juste en bas, d'vant ton bât'" J'ai l'espoir qu'elle attende ma venue, ma venue J'suis sur l'avenue, l'avenue, elle attend ma venue, ma venue Je sais qu'le printemps va finir Elle attend ma venue, ma venue, j'suis sur l'avenue, l'avenue J'ai aimé nos vacances à Venise mais je sais qu'le printemps va finir Elle attend ma venue, ma venue, j'suis sur l'avenue, l'avenue, eh Elle attend ma venue, ma venue, j'suis sur l'avenue, l'avenue J'suis sûr de rien, juste en un regard, j'ai plus confiance, han J'nous vois ensemble mais les fleurs poussent comme au printemps, han T'es dans l'attente, j'ai rien à t'offrir, j'ai même pas d'temps, han han Que des absences, han han Give me your hand Tous mes niggas, c'est des capos, on ne fait que mailler Et si c'est un dream, j'vais pas m'réveiller Y'a millions d'euros dans mon viseur, déception dans tes yeux Elle attend ma venue, ma venue, j'suis sur l'avenue, l'avenue J'ai aimé nos vacances à Venise mais je sais qu'le printemps va finir Elle attend ma venue, ma venue, l'avenue, l'avenue Ma venue, ma venue, l'avenue, l'avenue | I3: https://www.paroles.net/laylow/paroles-avenue | J3: 2026-10-21
A4: 14 | B4: Ciudad | C4: .RAW | D4: Laylow | E4: 553 | F4: 56 | G4: Et j'suis dans la ville avec mes associés, ça revient des Pays-Bas (ça revient des Pays-Bas) RDV toujours après minuit plutôt dans l'Est de la capitale (l'Est de la capitale) Porte des Lilas, hey, j'suis sur l'corner, j'ai l'maillot de l'Inter Milan (hey) 458 Italia, le bruit du pot qui fait peur aux femmes, hey Et fais pas trop l'mec qu'a des années d'avance, ça fait chier les gens Miky m'a dit : "Tu veux brasser mon fréro, fais pas trop l'intelligent" (beng beng) Té-ma, j'suis dans les temps, j'té-ma les gros culs, j'suis sur les Champs (yeah) Flammes dans les yeux d'Monsieur l'agent (yeah) dès qu'il a té-ma la taille des jantes Ouh babe, j'suis dans la ciudad, le vice est tout-par Salope est sous drugs, j'entends mais j'écoute pas Deux heures du mat', mets le coup d'casque J'mets le coup d'gaz, bébé, j'suis plus dans la ciudad Ouh babe, j'suis dans la ciudad, le vice est tout-par Salope est sous drugs, j'entends mais j'écoute pas Deux heures du mat', mets le coup d'casque (yeah) J'mets le coup d'gaz, bébé, j'suis plus dans la ciudad (dans la ciudad) J'suis dans la ciudad, le vice est tout-par Salope est sous drugs, j'entends mais j'écoute pas Deux heures du mat', mets le coup d'casque (yeah) J'mets le coup d'gaz, bébé, j'suis plus dans la ciudad (dans la ciudad) Yeah, yeah, yeah, yeah, yeah, yeah, yeah, yeah, yeah, yeah, yeah Everyday, j'fais mieux qu'yesterday, v'là la liste d'actes manqués Té-ma celle des appels manqués, même pas j'les rappelle après J'm'en bats les couilles d'la vie des an-ien-cs Ça rentre, le banquier fait "yes", les autres, j'les laisserai en iench Que pour ma que-cli, bah ouais faut beaucoup plus de power Le flow du Lay' envoie loin, tu kickes et forcément, c'est moins bien J'suis Yoda, t'es jeune padawan (padawan), hey, oulalala, hey Tu veux ton coup ? Va là-bas, ient-cli veut toute l'armada J'fais des écarts sur la route toute la night (hey) Deux-trois longueurs dans la swimming pool (swimming pool) J'écoute le projet en boucle, j'trouve j'ai un putain d'groove (putain d'groove) T'as poussé des tonnes mais tes bras sont pas bulletproof (bulletproof) Trou d'boulettes, j'roule, quand même "doré" tous les jours (ouh ouh) Ouh babe, j'suis dans la ciudad, le vice est tout-par Salope est sous drugs, j'entends mais j'écoute pas Deux heures du mat', mets le coup d'casque J'mets le coup d'gaz, bébé, j'suis plus dans la ciudad Ouh babe, j'suis dans la ciudad, le vice est tout-par Salope est sous drugs, j'entends mais j'écoute pas Deux heures du mat', mets le coup d'casque (yeah) J'mets le coup d'gaz, bébé, j'suis plus dans la ciudad (dans la ciudad) J'suis dans la ciudad, le vice est tout-par Salope est sous drugs, j'entends mais j'écoute pas Deux heures du mat', mets le coup d'casque (yeah) J'mets le coup d'gaz, bébé, j'suis plus dans la ciudad (dans la ciudad) J'suis plus dans la ciudad Bébé, j'suis plus dans la ciudad, hey J'suis plus dans la ciudad Bébé, j'suis plus dans la ciudad, ciao Hey, ah ouais Laylow les ken, c'est normal et bah ouais Hey, yeah, Digital Mundo baby, bah ouais, hein Dioscures Mami est dans la Hey Yeah | I4: https://www.paroles.net/laylow/paroles-ciudad | J4: 2026-10-21
A5: 22 | B5: Draxter | C5: .RAW | D5: Laylow | E5: 448 | F5: 43 | G5: C'est quelle basse du pack ? Bébé, t'es bonne sous plug Les projets, les billets qui pleuvent, uh, les mamans, les bébés qui pleurent Mes flows, c'est des fléchettes au cœur, tu veux mon prix c'est celui de la peuf J'remets les pendules à l'heure, j'suis dans la tech, j'suis dans l'ordinateur (ouh) Oh shit, quatre mecs bourrés dans le Audi J'envoie que des ogives, amoureux des gros chiffres Fuck, j'suis l'premier en cash, j'suis dans l'tunnel, la fin approche Changement d'ambiance et de langage, eh, ah gars Nouveau jet-pro, que des bangers, tu vas dead comme Rebenga J'te baise une fois, j'reviens pas, nan, j'reviens pas De Paname à L.A., de L.A. à Panama, hey, Santa Monica, pas Palavas Péta la SACEM à Balavoine Elle veut nouveau Gucci, Gucci, elle aura pas J'ai d'jà nouvelle bitchies sexy dans mon radar J'suis dans mon documentaire et y'a Manos à la caméra Dégaine de footeux dans Panamera, viens pas faire la pétasse, on vend plus la gue-dro Bitch, j'te sens lo-low, tout est sous contrôle Oh la, nouveau flow, ça download T'as gée-chan pour vingt dollars 'spèce de folle Tous mes frères font lol nouveau flow, ça download Bitch, j'te sens lo-low, tout est sous contrôle Oh la, nouveau flow, ça download T'as gée-chan pour vingt dollars 'spèce de folle Tous mes frères font lol nouveau flow, ça download Allez, fuck with me, j'suis dans l'banc depuis mes seize piges, j'suis l'Man of the Year (j'suis l'Man of the Year) Stoppe toutes tes tentatives comme Thiago Silva, comme Manuel Neuer (comme Manuel Neuer) Le talent, faut l'monnayer, j'suis dans l'money time, on rentre le lay-up (yeah) Sélection des meilleurs, bitch en a plein les yeuz Donc bats les couilles d'ton keum, bats les couilles d'ton game (DigitalMundo babe) J'suis en apesanteur, lady bien sûr que la gov' est louée À l'intérieur, on est tous à l'Ouest comme un Yakuza tout tatoué J'suis tout tatoué, j'ai rien à perdre, tout à jouer Tous mes associés sont plutôt doués, si j'compte te baiser, j'vais pas t'ajouter J'vais pas t'ajouter (j'vais pas t'ajouter), t'as vu qu'la fumée quand on t'a doublé On t'la fait dans la vie comme à la Play', mets le replay, remets une 'teille, Lay' Bitch, j'te sens lo-low, tout est sous contrôle Oh la, nouveau flow, ça download T'as gée-chan pour vingt dollars 'spèce de folle Tous mes frères font lol nouveau flow, ça download Bitch, j'te sens lo-low, tout est sous contrôle Oh la, nouveau flow, ça download T'as gée-chan pour vingt dollars 'spèce de folle Tous mes frères font lol nouveau flow, ça download | I5: https://www.paroles.net/laylow/paroles-draxter | J5: 2026-10-21
A6: 23 | B6: Elephant | C6: .RAW | D6: Laylow | E6: 581 | F6: 54 | G6: 225, téma mes éléphants dans la clairière (yeah) 220 km/h dans la gova, mes gavas font "yeah yeah" (yeah yeah) Fais pas l'ancien papi, tous tes CDs sont rayés Deux fois plus chaud, on est toujours à chaud, on est toujours réveillés On pull up à quatre dans l'appart si tes potes ont pas payé 220 millions, c'est nada, sur Paname, demande à Ney Ney Fais pas l'ancien papi, tous tes CDs sont rayés J'arrive à fond dans la caisse, j'arrive en plein dans la tête Hun, elle cuisine le cake, cake, hun, elle veut son date, date Hun, ses seins sont fakes, fakes, hun, j'lui donne un fake name Ouh, mes gavas font "yeah, yeah", contents quand on est sur L.A Ouh, pour fêter mon birthday, j'me contenterai pas d'un Sundae J'me contenterai pas d'une seule 'teille, j'suis dans le stud', il est six o'clock J'me demande si bitch est sincère ou si c'est seulement du vice de forme Yeah, yeah, fashion killa gère la tendance depuis longtemps, ouais ouais (depuis longtemps) Mamacita veut qu'je parte j'lui dis qu'je n'ai pas l'time, oh man (oh man) J'arrive dans un Q7, j'le bois cul sec, vite fait (vite fait) Tu t'fais doubler vu qu't'es pas très discret, ouais, ouais (nan nan) J'suis v'nu dans ton stade pour climatiser, trop, trop frais, préviens l'régisseur Nouveau flow tout désabusé, yeah, yeah, yeah 225, téma mes éléphants dans la clairière 220 km/h dans la gova, mes gavas font "yeah, yeah" Fais pas l'ancien papi, tous tes CDs sont rayés Deux fois plus chaud, on est toujours à chaud, on est toujours réveillés On pull up à quatre dans l'appart si tes potes ont pas payé 220 millions, c'est nada, sur Paname, demande à Ney Ney Fais pas l'ancien papi, tous tes CDs sont rayés J'arrive à fond dans la caisse, j'arrive en plein dans la tête J'tape des barres quand tout l'monde dit qu'y'a plus d'espoir (y'a plus d'espoir) Té-ma ma clique remonte la pente en coupé sport (en coupé sport) J'suis dans la ville mais j'suis v'nu juste pour péter l'score (hey, hey, hey, hey) M'appelles pas par intérêt, m'appelles pas pour baiser c'soir (hey, hey, hey, hey) A j'ter des sorts, tu sers juste à j'ter des sorts J'parle pas trop gros, j'fais les sous, gros business sur téléphone, ah ouais c'fils de *bip*, c'est que des mythos Casquette Merco comme Hamilton, j'ai d'l'avance, j'sais pas combien d'tours J'suis là puis j'me téléporte, j'suis bon juste pour compter les sommes Pas b'soin d'un télescope pour voir qu'on l'fait pas comme les autres Maman avait raison, 225, c'est la vraie maison J'avance, tout est sombre, bitchies répètent que mon nom 225, téma mes éléphants dans la clairière 220 km/h dans la gova, mes gavas font "yeah, yeah" Fais pas l'ancien papi, tous tes CDs sont rayés Deux fois plus chaud, on est toujours à chaud, on est toujours réveillés 225, téma mes éléphants dans la clairière 220 km/h dans la gova, mes gavas font "yeah, yeah" Fais pas l'ancien papi, tous tes CDs sont rayés Deux fois plus chaud, on est toujours à chaud, on est toujours réveillés On pull up à quatre dans la party, tes potes ont pas payé 220 millions, c'est nada, sur Paname, demande à Ney Ney Fais pas l'ancien papi, tous tes CDs sont rayés J'arrive à fond dans la caisse, j'arrive en plein dans la tête Yeah Yeah, yeah, yeah, yeah | H6: Ah le mytho ? | I6: https://www.paroles.net/laylow/paroles-elephant | J6: 2026-10-21
A7: 30 | B7: Hi-fi | C7: .RAW | D7: Laylow | E7: 615 | F7: 63 | G7: Sur ma chaîne hi-fi (sur ma chaîne hi-fi) J'fais défiler les prods jusqu'à trouver la bonne Celle qui m'enverra loin d'ici (tellement loin) Ils nous regardaient dehors, j'avais prévenu mes homies J'savais d'jà qu'c'était difficile (tellement difficile) J'suis dans l'truc jusqu'aujourd'hui, même si musique a changé J'regrette rien, tout est magnifique (tout est magnifique) À part quelques moments (quelques moments), tellement de temps (tellement de temps) Perdu sur ma chaîne hi-fi J'suis dans la street, elle me té-ma, verre de whisky pour la démarrer J'ai fait un rêve, c'était très noir (très noir, très noir, très noir), très noir J'calcule le bénéf' en peignoir, j'ai fumé, j'peux pas J'ai d'jà mamacita dans la baignoire (okay-kay-kay-kay) Dix-huit piges, distribue tout dans la ciudad (ouh) Nigga, j'ai perdu des euros, j'ai toujours pas perdu la mémoire (nan, nan, nan) Tout est écrit dans le mémo', tout est retranscrit dans la mélo' (hey) Ces derniers temps, je suis sous l'eau, je sens l'calice au goulot, oh Je bois, je nage, j'te vois, j'me noie direct (direct) Bolide rate un virage, j'vais p't-être pas m'en tirer (pas m'en tirer) J'repense aux gens qui m'aiment, à ceux qui m'abîmaient J'repense aux nuits passées Sur ma chaîne hi-fi (sur ma chaîne hi-fi) J'fais défiler les prods jusqu'à trouver la bonne Celle qui m'enverra loin d'ici (tellement loin) Ils nous regardaient dehors, j'avais prévenu mes homies J'savais d'jà qu'c'était difficile (tellement difficile) J'suis dans l'truc jusqu'aujourd'hui, même si musique a changé J'regrette rien, tout est magnifique (tout est magnifique) À part quelques moments (quelques moments), tellement de temps (tellement de temps) Perdu sur ma chaîne hi-fi Paraît qu'on est déter', paraît qu'y'en a qui se sont endettés J'en ai rien à péter, au city on n'a pas bougé de l'été On freestyle, j'rafale comme un AK, branché sur la hi-fi, mets les effets Eh, maintenant c'est la mais quand je serai grand, je serai refait J'ai dit : "Quand je serai grand, je serai refait", toi, tu seras refaite J'espère j'aurais le Fefe, j'espère qu'il restera chose à fêter J'espère qu'il restera quelques fêlés pour taper mon nom dans la barre de recherche (barre de recherche) Et quand tu mettras le replay, tu verras qu'on regardait que nos reflets, shit C'est générationnel, baby, c'est jamais rationnel (jamais rationnel) Comment t'expliquer qu'on est plus Zizou que Lionel ? (plus Zizou que Lionel) Tacle à la ge-gor, si t'es Gattuso, j'suis Bommel (hey) Nigga, n'en restera qu'un comme à la lutte gréco-romaine (hey hey) Et des fois, j'me promène (yeah), j'repense à tout c'qu'on s'est promis (promis) J'suis toujours ce jeune nigga prospère (prospère), toi, jusqu'à quand t'es mon homie ? (jusqu'à quand ?) J'ai toutes les cartes, je fais all-in (all-in), béni comme les années 2000 (2000) On refera tourner nos vieux disques Sur ma chaîne hi-fi (haaan) J'fais défiler les prods jusqu'à trouver la bonne Celle qui m'enverra loin d'ici (tous les ) Ils nous regardaient dehors, j'avais prévenu mes homies J'savais d'jà qu'c'était difficile (je l'savais, je l'savais, je l'savais) J'suis dans l'truc jusqu'aujourd'hui, même si musique a changé J'regrette rien, tout est magnifique (tout est magnifique) À part quelques moments, tellement de temps Sur ma chaîne hi-fi (sur ma chaîne hi-fi) J'fais défiler les prods jusqu'à trouver la bonne Celle qui m'enverra loin d'ici (tellement loin) Ils nous regardaient dehors, j'avais prévenu mes homies J'savais d'jà qu'c'était difficile (tellement difficile) J'suis dans l'truc jusqu'aujourd'hui, même si musique a changé J'regrette rien, tout est magnifique (tout est magnifique) À part quelques moments (quelques moments), tellement de temps (tellement de temps) Perdu sur ma chaîne hi-fi | H7: ? | ? | I7: https://www.paroles.net/laylow/paroles-hi-fi | J7: 2026-10-21
A8: 43 | B8: Médaille | C8: .RAW | D8: Laylow | E8: 366 | F8: 41 | G8: Eazy Dew pétasse Han, fashion killa, j'suis sur la playa Ola c'est Pattaya, ohlala Laylow les graille, yeah Putain, j'suis high, si ça rappelle répond pas, yeah J'ai beau être ailleurs, vengeance au fusil mitrailleur, yeah, yeah, yeah Ça toque toque, t'as pas payé yeah, yeah, yeah Forcément, faudra s'réveiller et attendre Man of the Year Tous les ans j'suis que le énième J'suis p't-être pas fait pour régner mais jamais j'déposerai les armes Surtout si princesse a versé des larmes J'ai, j'ai travaillé jusqu'à deux du mat', jamais j'suis jamais l'employé du mois Pourtant, j'ai pedigree phénoménal Et les bitches veulent le ménage, elle a l'pétard à Nicki Minaj J'suis dans la cuisine, elle défait ses sapes, nigga, t'es Krilin, j'suis Vegeta Really, really, que des détails, sur un feeling, j'ai fait le pire Tu mérites vraiment pas la médaille, ton rire me manque et je m'égare J'fais des conneries quand il est tard, j'éteins la concu', j'allume un pétard J'vois le virage et je dérape Folie (really, really), han Hier soir, j'ai fait des folies (really, really), yeah La bitch était sous molly, j'dois r'monter la coline Elle est montée dans mon bolide (really, really) Oh, c'est des folies (really, really) Hey, hey, hey Baby était tellement bad, baby est infréquentable, yeah, yeah J'sais pas, j't'ai branché sans fil, l'impression que j' dans un film Quand tu danses en Wonderbra, j'suis blasé, j'ai drapeau blanc Elle veut mesurer ma folie, j'lui dis de grimper dans l'bolide J'traîne dans la street avec Manos en Balmain J'veux faire le tour de la Terre, de la jungle à la favela T'inquiète, j'suis bien maman, t'inquiète, y'a tous mes associés tout près de moi Tu sais, c'est dur, on est très demandé, j'peux pas rentrer ce soir Et demain soir aussi, mon ego qui grossit J'suis l'taureau pas docile, défoncé dans l'Audi Y'en a qui méritent des bisous, y'en qui méritent le uzi Mais toi, tu mérites ma folie (really, really) Folie (really, really), han Hier soir, j'ai fait des folies (really, really), yeah La bitch était sous molly, j'dois r'monter la coline Elle est montée dans mon bolide (really, really) Oh, c'est des folies (really, really) | H8: ? | I8: https://www.paroles.net/laylow/paroles-medaille | J8: 2026-10-21
A9: 55 | B9: Pk tu m'interesse | C9: .RAW | D9: Laylow | E9: 544 | F9: 57 | G9: Haaan, haaan Han, han, han, han Han, han, han (Benjay Beatz) Mais pourquoi tu m'intéresses ? Tu m'intéresses Sûrement pour une photo postée sur Internet, sur Internet J'peux pas lui briser le cœur mais j'lui casse le reste, j'te casse les reins 2018, j'suis phénoménal, big up à ceux qui m'ont nominés J'comprends pas l'comment du pourquoi tu m'intéresses, tu m'intéresses Sûrement pour une photo postée sur Internet, sur Internet J'peux pas lui briser le cœur mais j'lui casse le reste, j'te casse les reins 2018, j'suis phénoménal, big up à ceux qui m'ont nominés Mexico, Mexico, Mexico babe Trente-huit degrés dans la fosse, dans la canette de Tropico fraîche, hey Qu'j'arrive en tro-mé, qu'j'arrive en Cabriolet, c'est toujours all eyes on me Girls, niggas d'vant la son-mai, all eyes on me Forcément, j'ai vision rouge Deux heures du mat' jusqu'au lever du jour Moteur de moto fait vroum, vroum, vroum, vroum Toi, t'as pas toqué, t'es rentrée puis boum, boum, boum Mais pourquoi tu m'intéresses ? Tu m'intéresses Sûrement pour une photo postée sur Internet, sur Internet J'peux pas lui briser le cœur mais j'lui casse le reste, j'te casse les reins 2018, j'suis phénoménal, big up à ceux qui m'ont nominés J'comprends pas l'comment du pourquoi tu m'intéresses, tu m'intéresses Sûrement pour une photo postée sur Internet, sur Internet J'peux pas lui briser le cœur mais j'lui casse le reste, j'te casse les reins 2018, j'suis phénoménal, big up à ceux qui m'ont nominés, j'comprends pas comment J't'oublierai pas, tu m'as nominé, j'suis métissé, cheveux gominés, taureau dans corrida Hey, va pour les dominer, pas pour le copinage, fumée dans Cohiba, flex (flex) J'kicke et c'est terminé, vite fait, bien fait comme préliminaires Toute ton équipe est éliminée, limitée, mon potentiel est illimité Really bitch ? Accepte toutes sortes de liquide J'suis sur la côte, j'ai mon jus d'litchi, nouveau flow technique comme ju-jitsu J'suis 2-25, toi, qui es-tu ? J'illumine la ville comme Billie Jean En 82, mille excuses, 93 est le millésime Mais pourquoi tu m'intéresses ? Tu m'intéresses Sûrement pour une photo postée sur Internet, sur Internet J'peux pas lui briser le cœur mais j'lui casse le reste, j'te casse les reins 2018, j'suis phénoménal, big up à ceux qui m'ont nominés J'comprends pas l'comment du pourquoi tu m'intéresses, tu m'intéresses Sûrement pour une photo postée sur Internet, sur Internet J'peux pas lui briser le cœur mais j'lui casse le reste, j'te casse les reins 2018, j'suis phénoménal, big up à ceux qui m'ont nominés J'ride dans la ciudad, bébé, toute la night J'refais l'tour du périph', j'refais l'tour d'ma life Nigga, faut pas m'louper si tu sors le nine 2018, j'suis phénoménal, yeah, yeah, yeah, yeah Mais pourquoi tu m'intéresses ? Tu m'intéresses Sûrement pour une photo postée sur Internet, sur Internet J'peux pas lui briser le cœur mais j'lui casse le reste, j'te casse les reins 2018, j'suis phénoménal, big up à ceux qui m'ont nominés J'comprends pas l'comment du pourquoi tu m'intéresses (pourquoi tu m'intéresses ?) Sûrement pour une photo postée sur Internet (une photo postée sur Internet) J'peux pas lui briser le cœur donc j'lui casse le reste (oh, je casse le reste) 2018, j'suis phénoménal Pourquoi tu m'intéresses ? Sûrement pour une photo postée sur Internet | I9: https://www.paroles.net/laylow/paroles-pk-tu-m-interesse | J9: 2026-10-21
A10: 62 | B10: .RAW | C10: .RAW | D10: Laylow | E10: 334 | F10: 30 | G10: Tu m'as parlé vrai mais c't'ait trop tard J'avais d'jà cool-al dans prostate, tout dans ma rotation À part p't-être un avocat mais t'as capté, j'voulais palper la totale Maintenant que j'peux fixer les rotas, j'veux putain d'auto quand j'fais des photos Mais je sais c'est quoi mon taf, j'm'enregistre moi-même, c'est moi, j'veux mes montants Tu n'as pas l'gab' pour le faire, keumé, reste à ta place J'vole dans la ciudad comme un prince au Qatar sur son deltaplane C'est chaud mais c'est qu'la mise à plat, pull up le track, j'suis dans un classe C Concentré comme avant l'casse-pipe, j'repense à tout c'qu'on n'a pas fait J'le conjugue toujours à l'imparfait comme Paname et Ben Arfa Et quand j'trouve pas Morphée, j'fais cinquante lignes en un quart d'heure J'les jette en l'air comme actrice X, jamais c'est l'armistice Nique tes statistiques J'démarre le Tmax, tu té-ma, té-ma la démarche, j'ai l'pantalon bas et les TN Regarde la BM, ce-vi gravé dans l'ADN Bitchies veut toujours glisser dans mes DMs, j'sais pas pourquoi ça m'intéresse Écoute, on t'attend sur le terrain juste pour vérifier si t'es réel, ouais, ouais J'dérape en R1, j'pose, ça fait les terrains 404 bébé, y'a erreur, tu nous a pris pour ces keumés tout péraves Fais gaffe, j'rappe, ouais, je les terrasse, Digitalova la menace tenace Tu veux changer l'entraîneur ? Tu perds à domicile, à l'extérieur, ouais, ouais T'inquiètes j'traîne avec DZ, tu valides en deux seizes Concu' fait "ohlala", j'vais gagner haut la main, j'veux pas les check (les check hun hun) J'rentre à la baraque, a fait des empanadas, trouve pas d'prétextes (trouve pas d'prétextes) J'fais pas de turnover, j'arrive et game over, les spots, c'est dead (ouh) Woh, tes gavas sont woh J'les vois d'en haut, j'suis dans les airs à la Kobe 'Pissez d'ssus c'est mon ho-bby L'jour où ça tombe, on fait "woh" (woh) Si ça tombe pas, on fait autre chose, demande pas Laylow | I10: https://www.paroles.net/laylow/paroles-raw | J10: 2026-10-21
A11: 5 | B11: Amy | C11: .RAW-Z | D11: Laylow | E11: 440 | F11: 40 | G11: Nouveau flow wavy, tout en sous-marin, baby c'est la navy Remplis ton lait kids, baby j'ai rempli les poches de mon Levi's J'suis dans la playlist, j'suis dans la ville avec Fares et Nabil Demande à Amy, j'sais qu'on finira tous un peu dépressif J'suis dans la playlist, baby j'arrive au feu rouge, descend tes vitres Oublie tes crédits, oublie ton keumé, sa dégaine de gréviste Je sais qu't'es très triste, je sais qu't'as subis la moquerie, la traitrise Mais remet ta Gucci eh, relève la tête et vois plus loin qu'ton bout d'shit Eh, hey, éléphant criera pas "Mayday" (yeah yeah) J'suis dans la clairière, jamais faut regarder derrière, yeah yeah Exception pour cul de guerrière, j'me métamorphose en bull terrier Mais j'la mets même si l'angle est fermé Nouveau flow wavy, tout en sous-marin, baby c'est la navy Remplis ton lait kids, baby j'ai rempli les poches de mon Levi's J'suis dans la playlist, j'suis dans la ville avec Fares et Nabil Demande à Amy, j'sais qu'on finira tous un peu dépressif Si y'a la somme, on y est, tu connais l'adresse e-mail Rajoute un dernier billet yeah, et toute la famille y est, yeah Si y'a la somme, on y est, bébé j'suis plus chaud qu'hier Rajoute un dernier billet yeah, et toute la famille y est, yeah Lay', wesh, 2018, ils nous craignent Remet une 'teille, remet mes projets, remet sur replays J'entoure les chiffres et les corps à la craie J'attends pas patron qui paye J'bosse everyday-day, toi, tu cours après les dates (okay) Nouveau flow wavy, pas comme le fake que t'as chopé sur le web, bitch Étoile comme Brésil, si c'était GTA, tu s'rais d'jà wasted Il faut des vrais chiffres, ceux qui font plais' à la vieille, à la main Demande à Amy, tu sais, ça peut s'arrêter à vingt-sept piges Ouais, demande à Amy, demande à ceux qui s'mettent six cents balles dans le pif Hun, comment c'est d'écouter mes flows sous cocaïne Fuck you baby, j'suis dans le tunnel, le voyant s'éternise Nouveau flow wavy, tout en sous-marin, baby c'est la navy Remplis ton lait kids, baby j'ai rempli les poches de mon Levi's J'suis dans la playlist, j'suis dans la ville avec Fares et Nabil Demande à Amy, j'sais qu'on finira tous un peu dépressif Si y'a la somme, on y est, tu connais l'adresse e-mail Rajoute un dernier billet yeah, et toute la famille y est, yeah Si y'a la somme, on y est, bébé j'suis plus chaud qu'hier Rajoute un dernier billet yeah, et toute la famille y est, yeah | H11: ? | I11: https://www.paroles.net/laylow/paroles-amy | J11: 2026-10-21
A12: 10 | B12: Bruits de couloir | C12: .RAW-Z | D12: Laylow | E12: 320 | F12: 37 | G12: Oh, elle arrive et même si ça sent bon J'suis toujours là dans l'ombre à répéter Qu'j'suis l'homme de l'année, yeah J'vois s'écouler le temps pendant qu'maman m'attend Lay', j'arrive c'est tout noir, bitchy m'attend dans le fumoir (yeah yeah) J'entends des bruits dans le couloir, fuck, c'est que des loux-ja, leurs comptes est tout dans le rouge Fuck avec nous dans la loge, j'suis dans le club hallelujah Ouh wa, niquer la concu' c'est tout moi, yeah, yeah 225, on est sournois, yeah, yeah Baby, les culottes ont tournoyées, yeah yeah Et le patron du club va nous vouvoyer, yeah yeah Si y'a mon nom sur le flyer, yeah (yeah yeah) yeah (yeah yeah) On n'oubliera pas les leçons d'hier, yeah (yeah yeah) yeah (yeah yeah) Même si le club est sous coca' (ïne) Oh, elle arrive et même si ça sent bon J'suis toujours là dans l'ombre à répéter Qu'j'suis l'homme de l'année, yeah J'vois s'écouler le temps pendant qu'maman m'attend J'ressors du club, il est deux heures, j'ai laissé bitch au coin fumeur J'recompte la liasse, y'a mille cinq cents e et c'est trop peu Déçu comme à l'époque où j'découpais mes plaquettes Comme quand j'partais au basket et que j'prenais soixante-sept Mingo sonne, j'espère que c'est pour du sale J'viens pas dans ton after juste pour boire du sky' Y'a rien à fêter mon négro, j'suis dans l'mal J'pense à stopper, j'te parle sah, donne-moi ce-for si t'as ça J'suis dans l'flou de cinq à sept, j'fais des pompes, j'ai l'bras cassé J'lui d'mande si j'en fais assez, si j'dois tricher comme Nasser Pour finir c'qu'est commencé, cracher sur c'qu'est romancé Être prêt à tout r'commencer Oh, elle arrive et même si ça sent bon J'suis toujours là dans l'ombre à répéter Qu'j'suis l'homme de l'année, yeah J'vois s'écouler le temps pendant qu'maman m'attend Digitalova, El Mundo 225, éléphant Tremblement, tremblement d'terre | I12: https://www.paroles.net/laylow/paroles-bruits-de-couloir | J12: 2026-10-21
A13: 28 | B13: Hello RAW.Z | C13: .RAW-Z | D13: Laylow | E13: 150 | F13: 24 | G13: Hello, mélancolie est là Hello, mélancolie est là Passe à la casa baby, j'suis là Ramène la sson-boi, on s'met minable Hello, mélancolie est là Hello, mélancolie est là Passe à la casa baby, j'suis là Ramène la sson-boi, on s'met minable J'voulais écrire des sons positifs Mais j'crois qu'y'en a aucun dans mon dix titres (shit) .RAW-Z, c'est la B.O de ton suicide C'est tellement triste qu'la météo s'fait du soucis Rajoute des glaçons dans la liqueur (glou glou glou glou glou) Prend soin d'moi comme un babysitter Tu sais comment glacer mon p'tit cœur J'espère qu'cette mélo va te plaire Hello, mélancolie est là Hello, mélancolie est là Passe à la casa baby, j'suis là Ramène la sson-boi, on s'met minable Hello, mélancolie est là Hello, mélancolie est là Passe à la casa baby, j'suis là Ramène la sson-boi, on s'met minable | I13: https://www.paroles.net/laylow/paroles-hello-raw-z | J13: 2026-10-21
A14: 32 | B14: I don't : need u / know | C14: .RAW-Z | D14: Laylow | E14: 945 | F14: 104 | G14: I don't need you M'envoie pas des ssages-me Baby, t'as vu mes yeux Ouais, t'étais désarmée Yeah, han sur ma tout dans l'enveloppe Elle veut l'dernier Gucci à la mode J'ai besoin du seille-o, j'ai pas b'soin du love Cent kilos, nigga, j'développe ? Donne-nous l'biff, donne-nous pas le love Yeah yeah, y'a ton cul sur siège arrière Yeah, vroum vroum sur l'allée yeah yeah Ils f'raient todo un illet-b, yeah yeah Oh, fuck le dernier Gucci à la mode Faut faire percer tout les frères du mob Projet leak toi tu download Moi, comment j'fais pour péter collier tout en or ? Oh bah ouais, faut les uer-t' bien correctement Toi, t'es là, tu penses que t'es plus fort que moi Si tu casses, tu répares avec tes deux mains J'attends pas le lendemain I don't need you M'envoie pas des ssages-me Baby, t'as vu mes yeux Ouais, t'étais désarmée Han, sur ma tout dans l'enveloppe J'ai besoin du seille-o, j'ai pas b'soin du love Cent kilos, nigga, j'développe ? Donne-nous l'biff, donne-nous pas le love Elle veut s'approcher du Lay', I don't need you Elle veut le Man of the Year, I don't need you, I don't need you J'suis pas le Prince de Bel Air, j'suis pas un mignon, j'suis pas un mignon Si tu veux vraiment m'aider : donne-moi un million, j'suis dans l'avion 225 à la vie à la mort, dis moi t'es qui, on fait que des biz à la Fillon, hey Tu veux ken ? Nan, pas maintenant, prends un ticket, fais la queue comme au In-N-Out Mets la bass, mets la jusqu'au maximum Faut qu'on m'entende dans tout ton bâtiment Si ta vie est triste babe, j'ai pas l'antidote Lay' I don't need you M'envoie pas des ssages-me Baby, t'as vu mes yeux Ouais, t'étais désarmée Han, sur ma tout dans l'enveloppe J'ai besoin de l'oseille, j'ai pas b'soin du love Cent kilos, nigga, j'développe ? Donne-nous l'biff, donne-nous pas le love Shit, c'est qui ça encore ma gueule ? Hello, fils de veut m'signer pour quelques euros, j'dis : "C'est chaud" Oh no, j'rentre à Toulouse, les gars m'demandent : "Wesh, alors ? C'est quand tu sors un nouveau truc de ouf ?" mais nan Tu veux Laylow dans ta ciudad, appelle ici ou mon Moi, j'veux toujours ma putain d'bête de villa sur la côte Il m'faut ma colombienne, il m'faut mes marmots pieds dans l'eau D'mande à Tony M, on a des manos faites pour l'or C'est combien pour la Murcielago ? Don't know (hey hey) Combien pour faire rentrer tout mes kho ? Don't know (hey hey) Combien pour qu'tu vendes le cul d'ta go ? Don't know (hey hey) Combien d'projets pour qu'ils comprennent qu'on les fuck ? (fuck) J'monte sur scène, cette nuit, j'mets l'club à l'envers (club à l'envers) Pourquoi tous ces fils de putes veulent encore nous test ? (tu veux encore nous test) I don't know, I don't know, I don't know Ohlala, j'le fais mieux qu'vous les mecs Hello, fils de veut m'faire signer plein, plein d'papier, j'lui dis : "No, nique tes morts" J'attrape reste de concu' par le lobe, j'la toast J'peux plus m'permettre de trainer dehors et d'vendre la dope, no Laylow les canne des-pi sur ma ive Si j'l'ai pas fait, c'est qu'avant j'étais naïf Poto, j't'aimais d'tout mon cœur, tu m'as trahi Résultat : y'a plus ton se-bla sur la liste Flex, flex, flex Hello, fils de veut m'signer pour quelques euros, j'dis : "C'est chaud" Oh no, j'rentre à Toulouse, les gars m'demandent : "Wesh, alors ? C'est quand tu sors un nouveau truc de ouf ?" mais nan Tu veux Laylow dans ta ciudad, appelle ici ou mon Moi, j'veux toujours ma putain d'bête de villa sur la côte Il m'faut ma colombienne, il m'faut mes marmots pieds dans l'eau D'mande à Tony M, on a des manos faites pour l'or C'est combien pour la Murcielago ? Don't know (hey hey) Combien pour faire rentrer tout mes kho ? Don't know (hey hey) Combien pour qu'tu vendes le cul d'ta go ? Don't know (hey hey) Combien d'projets pour qu'ils comprennent qu'on les fuck ? (fuck) M'regarde pas dans les yeux, tu vas t'brûler la rétine Pourquoi s'péter un gun ? Tout l'monde sait qu'tu sais pas rer-ti, hey Elle veut des grammes et des eu, elle prend des poids et des pénis (really ?) uh Tu veux pas partager mais quand ça pète tu dis qu'tu l'avais prédis 225, on est béni, concu' sur Vélib', DJ a retweeté Leurs flows sont pénibles, j'suis tout en haut comme Soleil au zénith J'suis dans ma loge avec mes kho, rien qu'tu demandes des selfies Y'a qu'à mon bro qu'est d'jà en taule que j'peux donner du crédit Numéro uno dans l'tournament, technique comme Ocean's Eleven Maradona, j'ai pas mis les mains, elle est d'jà mouillée comme à la mer I don't know ouais, I don't know ouais I don't know ouais, I don't know Hello, fils de veut m'signer pour quelques euros, j'dis : "C'est chaud" Oh no, j'rentre à Toulouse, les gars m'demandent : "Wesh, alors ? C'est quand tu sors un nouveau truc de ouf ?" mais nan Tu veux Laylow dans ta ciudad, appelle ici ou mon Moi, j'veux toujours ma putain d'bête de villa sur la côte Il m'faut ma colombienne, il m'faut mes marmots pieds dans l'eau D'mande à Tony M, on a des manos faites pour l'or C'est combien pour la Murcielago ? Don't know (hey hey) Combien pour faire rentrer tout mes kho ? Don't know (hey hey) Combien pour qu'tu vendes le cul d'ta go ? Don't know (hey hey) Combien d'projets pour qu'ils comprennent qu'on les fuck ? (fuck) | H14: ? | ? | ? | ? | ? | ? | ? | I14: https://www.paroles.net/laylow/paroles-i-don-t-need-u-know | J14: 2026-10-21
A15: 40 | B15: Maladresse | C15: .RAW-Z | D15: Laylow | E15: 363 | F15: 38 | G15: J'sais qu'j'mérite pas tout cet amour qu'on m'adresse J'sais qu'tu mérites mieux, j'sais qu'j'suis plein d'maladresse Tu sais, le temps passe, y'a pas grand chose dans l'assiette Donc pour noyer ma rage, j'attends plus la fin d'la s'maine Hey hey (hey hey), hey hey (hey hey) Hey hey (hey hey), hey hey (hey hey) Hey hey (hey hey), hey hey (hey hey) Hey hey J'pète des seums quand y'a les porcs et les suceurs qui flex (hey) C'est les mêmes qui voulaient tout balance à la maîtresse, yeah Moi, mes res-frè, c'est des pits, ils sont sauvages J'connais toujours pas la pétasse qui m'tiendra en laisse, nan Rajoute un truc électronique, tu sais qu'c'est nous les plus bioniques 225, you know me, v'là les pompiers comme dans Blow, bitch Allez blow bitch, c'est ton hobbie, m'invite pas dans soirée cosy J'suis attachant mais j'suis nocif, on verra c'qu'en dit l'autopsie Ils f'ront comme si y'avait r Et quand l'FAMAS blesse, les egos se taisent Et quand l'témoin s'lève, j'suis toujours à l'aise Faut qu'j'me pète une caisse, assortie à mes textes Pour plus squatter la 13, pour faire plais' à ma mère Haaan Fuck cette musique et c'qui va avec Haaan J'aime cette musique, j'suis plus dans l'93, on a changé d'adresse, yeah Ni chaud, ni froid quand ce négro fait l'show à mes exs J'suis concentré que sur le tur-fu, ta que-cli régresse, ouh Démon me chuchote à l'oreille : "Mais démolie-les" Démon me dit qu'il faut rien oublier, toutes les défaites et les ennemis d'hier (yeah) Tous ces moment où t'es seul et tu t'sens humilié (yeah) Tous ces gens qui t'ont douillé, qui ont profité d'ta vision brouillée (hey) Oublie-les Ça, c'est mon ange qui revient dès que ma vision est nette Quand je suis maître de mes sentiments mais qui peut me test ? Qui peut le faire mieux que le Lay' ? Sûrement pas ceux qui passent à la télé Tu veux le Graal ? Je te le laisse, si t'as du mal, poto appelle J'avance à grands pas que dans les grandes choses Ça me dérange pas que tu captes tout avec tant de délai, Laylow | I15: https://www.paroles.net/laylow/paroles-maladresse | J15: 2026-10-21
A16: 58 | B16: Prince de sang mêlé | C16: .RAW-Z | D16: Laylow | E16: 606 | F16: 53 | G16: Jeune tis-mé court à sa perte, ouh qui aura sa peau ? J'suis blanc, j'suis couleur ébène, tu sais, je me rappelle J'voulais baiser des blondes dans l'dernier des Benz Noires mates comme mes ancêtres, c'est ma façon d'me venger Ouh, scooter en l'air, rajoute le majeur en l'air Repars dix piges en arrière et tu verras qu'on est toujours les mêmes, yeah "Le fait pas juste pour leur plaire", c'est c'que m'disait ma mère J'cours toujours après mes rêves, jeune tis-mé court à sa perte Hey, 225, yeah, you know me,j'fait du shit avec le cro-mi Les pousser jusqu'à l'agonie, jusqu'à la folie Toi, je sais pas, t'es mon homie, dis-moi si t'es mon homie Attends pas mon premier llion-mi, oh t'es pas mon homie Et j'pourrais jamais m'endormir yeah, si j'ai pas tous mes psychotiques yeah J'effraie, j'défraie la chronique, j'défais, j'refais pas son lit Et quand j'me dope comme un cycliste, au réveil, j'suis si triste C'est pas carré, c'est cyclique, c'est pas vraiment pareil quand j'y suis Mon grand, j'suis métissé, j'ai pas choisi un camp, pourquoi ces gens m'en veulent autant ? Pourquoi ils m'té-ma comme un Minotaure ? Han Prince de sang-mêlé les fera taire, les fera payer l'prix de sa peine, quitte à leur bourrer la te-tê à terme On connait les termes mais ils rédigent les contrats, baby, c'est toujours nous contre eux On affranchit pas un négro en lui payant des colliers, des montres J'comprends, tu veux montrer tout c'que tu possèdes de concret Mais les réseaux t'ont trompés, ta meuf t'a trompé, ton temps est compté, mon nigga oh yeah, yeah T'es vaillant mais la tête devant l'Himalaya Dis-leurs qu'on a faim, dis-leurs qu'on veut graille Qu'y'a toujours deux poids, deux tailles, j'entends, les darons font : "Aïe aïe aïe" 225 millions d'euros en tête, c'est pas assez pour s'libérer des chaînes Qui nous retiennent et nous montent à la tête, un stick et j'cours à ma perte Tu crois à nous mais j'pense à ma paire, j'en veux à la France mais j'pense à mon père J'finirai sûrement du plomb dans la tête comme mes ancêtres pendant la traite, hey Hey, 225, yeah, you know me, j'fait du shit avec le cro-mi Les pousser jusqu'à l'agonie, jusqu'à la folie Toi, je sais pas, t'es mon homie, dis-moi si t'es mon homie Attend pas mon premier llion-mi, oh t'es pas mon homie Et j'pourrais jamais m'endormir yeah, si j'ai pas tous mes psychotiques yeah J'effraie, j'défraie la chronique, j'défais, j'refais pas son lit Et quand j'me dope comme un cycliste, au réveil, j'suis si triste C'est pas carré, c'est cyclique, c'est pas vraiment pareil quand j'y suis (quand j'y suis) Hey, Prince de sang-mêlé T'es toujours des deux côtés Mais t'sais, ce double jeu n'peux plus durer Prince de sang-mêlé Tu vas t'emmêler Dans ce double jeu Hey, 225, yeah, you know me, j'fait du shit avec le cro-mi Les pousser jusqu'à l'agonie, jusqu'à la folie Toi, je sais pas, t'es mon homie, dis-moi si t'es mon homie Attend pas mon premier llion-mi, oh t'es pas mon homie Et j'pourrais jamais m'endormir yeah, si j'ai pas tous mes psychotiques yeah J'effraie, j'défraie la chronique, j'défais, j'refais pas son lit Et quand j'me dope comme un cycliste, au réveil, j'suis si triste C'est pas carré, c'est cyclique, c'est pas vraiment pareil quand j'y suis (pas vraiment pareil quand j'y suis) Ici, on travaille très dur et qu'est c'qu'on voit ? Tous ces sales nègres qui nous piquent notre fric pour acheter des voitures | I16: https://www.paroles.net/laylow/paroles-prince-de-sang-mele | J16: 2026-10-21
A17: 7 | B17: Bad Romance | C17: Digitalova | D17: Laylow | E17: 477 | F17: 46 | G17: Oh, là, j'suis dans cette merde depuis des années Trop la flemme de rester poli, j'vais lui parler comme un sauvage Rester spontané, j'fais mon show et j'prends mon cash et j'vais pas ger-chan pour une poignée d'dollars Juste une poignée d'dollars, RocknRolla bébé, ferme ton Motorola J'suis sur l'corner, j'ai mes corro', ma Corona, quelques gouttes en hommage à tout ceux en haut Oh, j'le vois bien, t'es en trance, tu veux danser C'est chaud, j'ai mes torts, t'as les tiens, qui peut trancher ? T'es bonne mais tu snobes comme si j'te parlais pas français La taille, les détails, t'avais tout donc j'ai flanché Oh mama, oh mama, oh mama, tu sais, j'pense à toi, toutes les fois où elle me rend malade Oh, oh, oh mama, oh mama, oh mama, tu sais, j'pense à toi toutes les fois où elle me- Tu déchaines mes démons Dès minuit, ça commence et sans cesse, tu relances, tu demandes, tu demandes Mais j'ai pas les réponses à tes questions, retente dans deux mois, dans deux mois Dès minuit, ça commence et sans cesse, tu relances, tu demandes, tu demandes Mais j'ai pas les réponses à tes questions, retente dans deux mois, dans deux mois Oh, j'le vois bien, t'es en trance, tu veux danser C'est chaud, j'ai mes torts, t'as les tiens, qui peut trancher ? Hey, tu connais mon name (Tu connais mon name) Tu connais mes règles (Tu connais mes règles) J'ai que mon honneur (J'ai que mon honneur) Et un peu d'oseille (Et un peu d'oseille) Les condés nous testent (Les condés nous testent) J'réponds pas quand ils nous questionnent J'appuie jamais sur le frein (J'appuie jamais sur le frein) Même quand j'ai crevé la roue (Même quand j'ai crevé la roue) J'suis à cent-quatre-vingt-dix (J'suis à cent-quatre-vingt-dix) J'ai doublé la Subaru (J'ai doublé la Subaru) On est v'nu défier la vie (On est v'nu défier la vie) Souviens-toi d'c'qu'on avait dit (Souviens-toi d'c'qu'on avait dit) Qu'on niquerait tout sur un feeling, hey Oh, j'le vois bien, t'es en trance, tu veux danser C'est chaud, j'ai mes torts, t'as les tiens, qui peut- Oh, oh, j'le vois bien, t'es en trance, tu veux danser C'est chaud, j'ai mes to- Tu déchaines mes démons Dès minuit, ça commence et sans cesse, tu relances, tu demandes, tu demandes Mais j'ai pas les réponses à tes questions, retente dans deux mois, dans deux mois Dès minuit, ça commence et sans cesse, tu relances, tu demandes, tu demandes Mais j'ai pas les réponses à tes questions, retente dans deux mois, dans deux mois Moi, j'suis dans cette romance, romance, romance Et toi, tu demandes, demandes, demandes Moi, j'suis dans cette romance, romance, romance Et toi, tu demandes, demandes, demandes Moi, j'suis dans cette romance, romance, romance Et toi, tu demandes, demandes | I17: https://www.paroles.net/laylow/paroles-bad-romance | J17: 2026-10-21
A18: 8 | B18: Bionic | C18: Digitalova | D18: Laylow | E18: 454 | F18: 66 | G18: Mami, yé le fuego dans la tête (Le fuego dans la tête) Deux heures du mat' dans la caisse (Deux heures du mat' dans la caisse) J't'ai même pas dis "hello" (J't'ai même pas dis "hello") Enchanté, moi c'est Laylow (Enchanté, moi c'est Laylow) J'ai peu d'temps à perdre (J'ai peu d'temps à perdre) D'habitude j'fais des business (D'habitude j'fais des business) Mais mami tu me plais trop (Tu me plais trop) J'te vois depuis le rétro (Depuis le rétro) J'essaie, (j'essaie), j'réessaie, (j'réessaie) Mais ces bâtards veulent pas me laisser Brasser tout seul dans mon coin Cet été, j'sors le TT J'te le promets mami, j'vais les laisser parler J'roulerais loin, loin, loin Han, tu m'illumines, surtout après minuit et demi T'es au top, t'es collée au rythme J'en oublie tous mes a priori Tu danses, flex, bionic J'suis déjà vintage comme G-Unit T'as grillé toutes les priorités T'es là mais j'ai du mal à me lancer, lancer, lancer, lancer, lancer Toute la nuit t'as dansé, dansé, dansé, dansé, dansé Comme si tu sentais même pas le danger, rentrer Dans tes draps, te tenter Écoutes pas les avis des gens Ils veulent t'enlever ta façon de penser C'est insensé Baby, why you don't come tonight ? Ouh babe We can do all the things you like, oh Come tonight Come, have some fun Baby, we can do all the things you like J'reviens plus déter' Second couplet coupe les têtes J'ai toujours pas mon coupé bébé Pourtant, j'ai rien loupé Chaud comme en Guadaloupe, faya man T'es là, tu fais qu'rouler d'l'herbe Donc je m'endors dans tes bras un moment Un moment, un moment, un moment Un moment, un moment, un moment T'as p't'être pris trop d'drogues cette nuit, et alors ? Mes ennemis reçoivent tête de mort J't'envois des smileys ma baby love À chaque fois, j'sais pas à quoi m'en tenir Tu vois pas où j'veux en venir ? T'es dans ma ligne de mire J'pense à toi, j'fais des vroum-vroum sur l'périph' Han, tu m'illumines, surtout après minuit et demi T'es au top, t'es collée au rythme J'en oublie tout mes a priori Tu danses, flex, bionic J'suis déjà vintage comme G-Unit T'as grillé toute les priorités T'es là mais j'ai du mal à me lancer, lancer, lancer, lancer, lancer Toute la nuit t'as dansé, dansé, dansé, dansé, dansé Comme si tu sentais même pas le danger, rentrer Dans tes draps, te tenter T'écoutes pas les avis des gens Ils veulent t'enlever ta façon de penser C'est insensé Baby, why you don't come tonight ? Ouh babe We can do all the things you like, oh Come tonight Come, have some fun Baby, we can do all the things you like | I18: https://www.paroles.net/laylow/paroles-bionic | J18: 2026-10-21
A19: 18 | B19: Digital Vice City | C19: Digitalova | D19: Laylow | E19: 498 | F19: 66 | G19: On s'est préparé à la mort (se préparer à la mort) En parlant d'amour (parlant d'amour) On s'est défoncé jusqu'à l'aube (défoncé jusqu'à l'aube) C'était digital Tête en bas, cul en haut Me dérange pas, j'suis en haut On est tout p'tit vue d'en haut, haut Tête en bas, cul en haut Me dérange pas, j'suis en haut On est tout p'tit vue d'en haut, haut, haut Ça vanne depuis voilà l'époque étant donné le temps qu'il faudra pour être pigé et puis l'heure qu'il est Sé-po dans l'allée elle attend qu'on lui paye le taxi, elle est plutôt déterminée J'vais pas m'éterniser mais j'ai pas terminé Déguisé l'arme et les vraies idées Service a dévissé, zéro passes décisives, quand on rendra visite, l'ennemi s'ra décimé, terminé On f'ra la fête, on s'en fout de c'que pense le voisin Pour ma génération qui cherche une raison d'vivre dans les grands magasins, oh no La chance, c'est qu'une pute qui s'arrête dans les photomatons Il reste que des photos quand elle part le matin J'me lèverai plus tôt comme un alpiniste J'ai foncé sur les les rhums daïquiri Elle m'a même pas éthylé, blasé sur Digital Vice City Hanté par des sales idées Vingt messages non lus mais j'les ai... Digital Vice, pédé mets l'price J't'emmène loin, négro refile tes miles Les requins pourraient me voler mon time J'préférai laisser mes blèmes-pro Addict à une seule dose, j'pratique plus Nintendo Pourquoi ils font tous mine d'être auchs ? Wesh On s'est préparé à la mort (se préparer à la mort) En parlant d'amour (parlant d'amour) On s'est défoncé jusqu'à l'aube (défoncé jusqu'à l'aube) C'était digital Tête en bas, cul en haut Me dérange pas, j'suis en haut On est tout p'tit vue d'en haut, haut Tête en bas, cul en haut Me dérange pas, j'suis en haut On est tout p'tit vue d'en haut, haut, haut Salope dans l'arène J'vois rouge comme un taureau et c'est pas un rêve J'ai fait tomber ma cigarette Devant la plus bonne du harem Tête en bas, cul en l'air J'sais pas comment elle s'appelle Mais elle a tout mis dans le paraître J'ai tout mis dans un moteur Ferrari Flow d'Italie, j'vais souffler sur les bougies à ton anniv' Tu peux pousser v'là les kilos, si t'as pas la mentale, tu pousses jamais que des caddies Un, dos, tres, que des hat-tricks Mama n'a jamais voulu d'un artiste La douleur vient des abysses J'la maquille et ça m'attriste Faut qu't'entendes ça, c'est plus vrai qu'des attentats, on fait pas les mêmes Taf, j' J'prends l'truc, j'le mets dans l'bon sens C'est Dieu qui s'occupera d'mon sort Quand à douze contre un, c'est ma mort qu'on trinque Mi amor, c'est Famille, amis, j'vous aime, c'est personnel Doggystyle, ça va crème Derrière la maison mère Elle veut un mec pas raisonnable J'veux des gosses pas des emmerdes, dis-moi C'qu'est vraisemblable, t'as la tête en bas, cul en l'air (cul en l'air) | H19: ? | ? | I19: https://www.paroles.net/laylow/paroles-digital-vice-city | J19: 2026-10-21
A20: 19 | B20: Digitalova | C20: Digitalova | D20: Laylow | E20: 430 | F20: 65 | G20: Y'a des bords dans la caisse De la drogue dans nos veines Tu m'appelles j'ai pas d'réseau Han, han, yeah Digitalova, m'en bats les c' d'ton number J't'amène à la maison Bébé, j'marque les buts, j'fais les passes décisives Rien à gratter d'plus, on plane au-d'ssus d'cette ville Ici bas, j'suis qu'un homme face au 6-6-6 Le monde est bien trop grand pour qu'on ai qu'une seule vie Y'a comme un feeling, j'suis défoncé, j'fais l'tour d'la ville Toi plus moi, à deux grammes dans ta Mini Fait pas des gimmicks, j'suis d'vant ton building Oulala, rejoins-moi juste pour la night Pirelli Yokohama Té-ma le rayon gamma J'illumine la ville mami J'demande pas como te llema Demande pas comment j'gagne ma life Dehors c'est des malades Laisse toi planer toute la night Y'a des bords dans la caisse De la drogue dans nos veines Tu m'appelles j'ai pas d'réseau Han, han, yeah Digitalova, m'en bats les c' ton number J't'amène à la maison Bébé, j'marque les buts, j'fais les passes décisives Rien à gratter d'plus, on plane au-d'ssus d'cette ville Ici bas, j'suis qu'un homme face au 6-6-6 Le monde est bien trop grand pour qu'on ai qu'une seule vie Je reviens comme ton papa en Hummer Changement de flow selon l'humeur Le numéro qu'on veut c'est le 1 Les autres on les oublie en une heure, ouais, ouais Y'a quelques euros dans tes narines Et ça y'est tu valides baby Tu connais les tarifs Les majors ont lancé les paris, j'arrive Vraiment fait doucement babe Vraiment fait doucement babe T'as les idées à l'envers Tête en bas, cul en l'air Bouillant, digital comme à Shibuya J'suis devant toi mais j'suis ailleurs au même moment Bébé, m'en veux pas bientôt, on sort du brouillard Mes frères recherchent, million dollars ou nada J'essaye, j'ressaye mais ces négros veulent toujours pas comprendre Tu saignes, je le sais Mais nos cœurs se serrent... Le temps d'un seize Y'a des bords dans la caisse De la drogue dans nos veines Tu m'appelles j'ai pas d'réseau Han, han, yeah Digitalova, m'en bats les c' ton number J't'amène à la maison Bébé, j'marque les buts, j'fais les passes décisives Rien à gratter d'plus, on plane au-d'ssus d'cette ville Ici bas, j'suis qu'un homme face au 6-6-6 Le monde est bien trop grand pour qu'on ai qu'une seule vie Bébé, j'marque les buts, j'fais les passes décisives Rien à gratter de plus, on plane au-d'ssus d'cette ville Digitalmundo babe Man of the Yeah-Yeah-Year | I20: https://www.paroles.net/laylow/paroles-digitalova | J20: 2026-10-21
A21: 24 | B21: Enlève le shirt (Interlude) | C21: Digitalova | D21: Laylow | E21: 347 | F21: 43 | G21: ...message. Donc tout va bien ici, ravi. Tout l'monde, tout l'monde s'porte bien. J'voulais t'dire quoi : j'monte la s'maine prochaine, donc on va s'péter en stud' comme d'habitude et j'sais pas si t'as écouté la prod là, mais gros, elle est trop lourde Enlève le shirt, enlève le shirt Enlève le shirt, enlève le shirt Enlève le shirt, enlève le shirt Enlève le shirt, enlève le Wow, y'en a pas deux comme aç Pour allumer ta ville au rayon gamma, genre Un point rouge sur ton thorax Headshot surtout quand j'ai pas l'moral J'ai pas l'moral et c'est pas l'moment (c'est pas l'moment) Faut qu'tes gamins puissent se rappeler d'nos noms Kiffe mon son ou quitte ce monde Le vice me tente à chaque seconde Ah, c'est chelou mais mon cerveau peut pas servir Ces écervelés, j'vais les fuck si ça d'vient nécessaire J'lui dis d'enlever le shirt mais elle veut pas s'laisser faire Elle est gaulée comme un poney, j'mets ses quatre jambes en l'air J'suis l'gardien de ma que-cli comme Manuel Neuer T'es l'employé du mois, j'suis l'Man of the Year, yeah, yeah J'viens buter l'cœur de pierre J't'enfonce toute ta team au marteau-piqueur Ok, j'ai fait tomber mon ice cream au fond de ton décolleté Dans la chambre d'hôtel à la Kurt Cobain J'me suis barré, elle est révoltée Minuit passé, tout se passe au feeling Pour mes gens qui vont de zéro à l'infini Lève le R1 comme à Philly On a fini d'faire les félés dans la ville, on est les félons Elle s'attache, le pénis est long comme le nom de famille d'un malgache Oh l'bâtard, allez rajoute la beuh dans l'tobacco Le produit d'la folie des ados, plus r'cherché qu'El Chapo, han Dans l'building , han L'insolence que t'adore Enlève le shirt, enlève le shirt Enlève le shirt, enlève le shirt Enlève le shirt, enlève le shirt Enlève le shirt, enlève le shirt Enlève le shirt, enlève le shirt Enlève le shirt, enlève le shirt Enlève le shirt, enlève le shirt Enlève le *Glitch* Soixante-dix, le deuxième était... | H21: Laylow | Laylow | Laylow & Sir'Klo | ? | Laylow & Sir'Klo | I21: https://www.paroles.net/laylow/paroles-enleve-le-shirt-interlude | J21: 2026-10-21
A22: 26 | B22: Gogo | C22: Digitalova | D22: Laylow | E22: 516 | F22: 57 | G22: Y en a que pour toi toi toi toi toi toi toi, tu le sais girl Y en a que pour toi toi toi toi toi toi toi, tu le sais girl Y en a que pour toi Comme si t'étais née fille unique et c'est peut-être le cas Je sais très peu d'choses sur ta vie, c'est pareil pour toi Tu n'sais rien sur moi A part que je n'ai pas d'swag et j'squatte, avec mon squad Les halls sales du sud de la ville Appelle-moi si jamais tu t'ennuis Même au milieu de la nuit, j'viendrai chez toi avec de la nouvelle weed Si tu n'fumes pas j'ai du Bel Air aussi Si tu n'tease pas non plus, j'écouterai tes désirs avant de t'donner du plaisir J'fais tout ça pour toi Qu'est-ce tu ferais pour moi ? Je n'ai pas ressenti une envie aussi intense depuis longtemps Depuis mes premières fois à l'époque où je baisais ces tass' dans le bâtiment Attends que j'mette mon téléphone en mode avion Y en a que pour toi, t'obnubilises ma vision Nos corps et nos sens c'est bien tout c'que nous avons Parlons pas d'amour, parlons de c'que nous savons Y en a que pour toi toi toi toi toi toi toi, tu le sais girl Y en a que pour toi toi toi toi toi toi toi, tu le sais girl T'as touché le gros lot , d'habitude je suis solo Digitalova , J'ai donné que d'la haine à ma sono Mon bif à la gogo Je m'en rappelle plus, j'étais sous l'eau Le respect c'est todo mais l'égo c'est corrosif Première fois je vois dans tes yeux , Tu cherches le meilleur J'suis le man of the year ha ha yeah yeah... Quoi, t'en as rien à cirer ? T'aurais pu essayer, voir si tu kiffes Mais tu reste incorruptible Comme si tu voulais me prouver qu'y'a des ke-trus qui n'ont pas de prix J'fais le tour d'la ville a 2-20, les yeux rivés sur la minuterie J'ai pas fini mon couplet, il est minuit pile Ta ligne est est contre productive girl Sur ma ive, tu sais pas à quel point t'es égoïste Autotuné à mort que des mélodies tristes Y en a que pour toi toi toi toi toi toi toi, tu le sais girl Y en a que pour toi, y en a que pour toi, y en a que pour toi Y en a que pour toi toi toi toi toi toi toi, tu le sais girl Y en a que pour toi, tu t'en fous de nous, tu te fous de moi Dis-moi qu'est-ce qu'on attend, honnêtement Rien nous empêche d'essayer Dis-moi juste un mot, oui ou non Demain j'te laisserai m'oublier Qu'est-ce qu'on attend, honnêtement Rien nous empêche d'essayer Dis-moi juste un mot, oui ou non Demain j'te laisserai m'oublier Perfect, perfect Give me your number, give me your number Toi, tu t'en fous de nous, tu te fous de moi ouais Ouais Y en a que pour toi Tu t'en fous de moi | H22: ? | ? | ? | ? | ? | ? | I22: https://www.paroles.net/laylow/paroles-gogo | J22: 2026-10-21
